<?xml version="1.0" ?>
<robot name="differential_drive_robot_version1" xmlns:xacro="http://www.ros.org/wiki/xacro">

<xacro:include filename="$(find differential_drive_robot_version1_description)/urdf/materials.xacro" />
<xacro:include filename="$(find differential_drive_robot_version1_description)/urdf/differential_drive_robot_version1.trans" />
<xacro:include filename="$(find differential_drive_robot_version1_description)/urdf/differential_drive_robot_version1.gazebo" />
<link name="base_link">
  <inertial>
    <origin xyz="9.6361831312612e-05 2.303873814576495e-17 0.05241925929524171" rpy="0 0 0"/>
    <mass value="1.673814560119945"/>
    <inertia ixx="0.004604" iyy="0.004515" izz="0.008425" ixy="0.0" iyz="0.0" ixz="-1e-06"/>
  </inertial>
  <visual>
    <origin xyz="0 0 0" rpy="0 0 0"/>
    <geometry>
      <mesh filename="file://$(find differential_drive_robot_version1_description)/meshes/base_link.stl" scale="0.001 0.001 0.001"/>
    </geometry>
    <material name="silver"/>
  </visual>
  <collision>
    <origin xyz="0 0 0" rpy="0 0 0"/>
    <geometry>
      <mesh filename="file://$(find differential_drive_robot_version1_description)/meshes/base_link.stl" scale="0.001 0.001 0.001"/>
    </geometry>
  </collision>
</link>

<link name="left_wheel_1">
  <inertial>
    <origin xyz="4.557835751282935e-07 -0.012499999999999983 4.708465804748041e-07" rpy="0 0 0"/>
    <mass value="0.17530087007031012"/>
    <inertia ixx="0.000123" iyy="0.000228" izz="0.000123" ixy="-0.0" iyz="0.0" ixz="-0.0"/>
  </inertial>
  <visual>
    <origin xyz="0.024208 0.11 -0.05" rpy="0 0 0"/>
    <geometry>
      <mesh filename="file://$(find differential_drive_robot_version1_description)/meshes/left_wheel_1.stl" scale="0.001 0.001 0.001"/>
    </geometry>
    <material name="silver"/>
  </visual>
  <collision>
    <origin xyz="0.024208 0.11 -0.05" rpy="0 0 0"/>
    <geometry>
      <mesh filename="file://$(find differential_drive_robot_version1_description)/meshes/left_wheel_1.stl" scale="0.001 0.001 0.001"/>
    </geometry>
  </collision>
</link>

<link name="caster_1">
  <inertial>
    <origin xyz="0.049999906857758174 1.472619208837029e-14 -0.009648093222833904" rpy="0 0 0"/>
    <mass value="0.22331961696192731"/>
    <inertia ixx="3.2e-05" iyy="3.2e-05" izz="4.7e-05" ixy="-0.0" iyz="0.0" ixz="-0.0"/>
  </inertial>
  <visual>
    <origin xyz="-0.000227 -0.0 -0.027432" rpy="0 0 0"/>
    <geometry>
      <mesh filename="file://$(find differential_drive_robot_version1_description)/meshes/caster_1.stl" scale="0.001 0.001 0.001"/>
    </geometry>
    <material name="silver"/>
  </visual>
  <collision>
    <origin xyz="-0.000227 -0.0 -0.027432" rpy="0 0 0"/>
    <geometry>
      <mesh filename="file://$(find differential_drive_robot_version1_description)/meshes/caster_1.stl" scale="0.001 0.001 0.001"/>
    </geometry>
  </collision>
</link>

<link name="right_wheel_1">
  <inertial>
    <origin xyz="4.5578366227733147e-07 0.012499999999999983 4.708465804748041e-07" rpy="0 0 0"/>
    <mass value="0.17530087007031012"/>
    <inertia ixx="0.000123" iyy="0.000228" izz="0.000123" ixy="0.0" iyz="-0.0" ixz="-0.0"/>
  </inertial>
  <visual>
    <origin xyz="0.024208 -0.11 -0.05" rpy="0 0 0"/>
    <geometry>
      <mesh filename="file://$(find differential_drive_robot_version1_description)/meshes/right_wheel_1.stl" scale="0.001 0.001 0.001"/>
    </geometry>
    <material name="silver"/>
  </visual>
  <collision>
    <origin xyz="0.024208 -0.11 -0.05" rpy="0 0 0"/>
    <geometry>
      <mesh filename="file://$(find differential_drive_robot_version1_description)/meshes/right_wheel_1.stl" scale="0.001 0.001 0.001"/>
    </geometry>
  </collision>
</link>

<joint name="Revolute 2" type="continuous">
  <origin xyz="-0.024208 -0.11 0.05" rpy="0 0 0"/>
  <parent link="base_link"/>
  <child link="left_wheel_1"/>
  <axis xyz="0.0 -1.0 0.0"/>
</joint>

<joint name="Rigid 3" type="fixed">
  <origin xyz="0.000227 0.0 0.027432" rpy="0 0 0"/>
  <parent link="base_link"/>
  <child link="caster_1"/>
</joint>

<joint name="Revolute 4" type="continuous">
  <origin xyz="-0.024208 0.11 0.05" rpy="0 0 0"/>
  <parent link="base_link"/>
  <child link="right_wheel_1"/>
  <axis xyz="0.0 1.0 0.0"/>
</joint>

</robot>
